{
 "cells": [
  {
   "cell_type": "code",
   "execution_count": 1,
   "metadata": {},
   "outputs": [
    {
     "name": "stderr",
     "output_type": "stream",
     "text": [
      "WARNING:root:Limited tf.compat.v2.summary API due to missing TensorBoard installation.\n",
      "WARNING:root:Limited tf.compat.v2.summary API due to missing TensorBoard installation.\n",
      "WARNING:root:Limited tf.compat.v2.summary API due to missing TensorBoard installation.\n",
      "WARNING:root:Limited tf.compat.v2.summary API due to missing TensorBoard installation.\n",
      "WARNING:root:Limited tf.compat.v2.summary API due to missing TensorBoard installation.\n",
      "WARNING:root:Limited tf.compat.v2.summary API due to missing TensorBoard installation.\n",
      "WARNING:root:Limited tf.summary API due to missing TensorBoard installation.\n"
     ]
    }
   ],
   "source": [
    "import tensorflow as tf"
   ]
  },
  {
   "cell_type": "code",
   "execution_count": 2,
   "metadata": {},
   "outputs": [
    {
     "data": {
      "text/plain": [
       "[PhysicalDevice(name='/physical_device:CPU:0', device_type='CPU'),\n",
       " PhysicalDevice(name='/physical_device:XLA_CPU:0', device_type='XLA_CPU')]"
      ]
     },
     "execution_count": 2,
     "metadata": {},
     "output_type": "execute_result"
    }
   ],
   "source": [
    "\n",
    "tf.config.list_physical_devices()"
   ]
  },
  {
   "cell_type": "code",
   "execution_count": null,
   "metadata": {},
   "outputs": [
    {
     "name": "stderr",
     "output_type": "stream",
     "text": [
      "WARNING:root:Limited tf.compat.v2.summary API due to missing TensorBoard installation.\n",
      "WARNING:root:Limited tf.compat.v2.summary API due to missing TensorBoard installation.\n",
      "WARNING:root:Limited tf.compat.v2.summary API due to missing TensorBoard installation.\n",
      "ERROR:root:Internal Python error in the inspect module.\n",
      "Below is the traceback from this internal error.\n",
      "\n",
      "ERROR:root:Internal Python error in the inspect module.\n",
      "Below is the traceback from this internal error.\n",
      "\n",
      "ERROR:root:Internal Python error in the inspect module.\n",
      "Below is the traceback from this internal error.\n",
      "\n"
     ]
    },
    {
     "name": "stdout",
     "output_type": "stream",
     "text": [
      "Traceback (most recent call last):\n",
      "  File \"/home/aiffel0042/anaconda3/envs/aiffel/lib/python3.7/site-packages/IPython/core/interactiveshell.py\", line 3418, in run_code\n",
      "    exec(code_obj, self.user_global_ns, self.user_ns)\n",
      "  File \"<ipython-input-3-2d4de0c6809b>\", line 1, in <module>\n",
      "    tf.__verion__\n",
      "AttributeError: module 'tensorflow' has no attribute '__verion__'\n",
      "\n",
      "During handling of the above exception, another exception occurred:\n",
      "\n",
      "Traceback (most recent call last):\n",
      "  File \"/home/aiffel0042/anaconda3/envs/aiffel/lib/python3.7/site-packages/IPython/core/interactiveshell.py\", line 2045, in showtraceback\n",
      "    stb = value._render_traceback_()\n",
      "AttributeError: 'AttributeError' object has no attribute '_render_traceback_'\n",
      "\n",
      "During handling of the above exception, another exception occurred:\n",
      "\n",
      "Traceback (most recent call last):\n",
      "  File \"/home/aiffel0042/anaconda3/envs/aiffel/lib/python3.7/site-packages/IPython/core/ultratb.py\", line 1170, in get_records\n",
      "    return _fixed_getinnerframes(etb, number_of_lines_of_context, tb_offset)\n",
      "  File \"/home/aiffel0042/anaconda3/envs/aiffel/lib/python3.7/site-packages/IPython/core/ultratb.py\", line 316, in wrapped\n",
      "    return f(*args, **kwargs)\n",
      "  File \"/home/aiffel0042/anaconda3/envs/aiffel/lib/python3.7/site-packages/IPython/core/ultratb.py\", line 350, in _fixed_getinnerframes\n",
      "    records = fix_frame_records_filenames(inspect.getinnerframes(etb, context))\n",
      "  File \"/home/aiffel0042/anaconda3/envs/aiffel/lib/python3.7/inspect.py\", line 1502, in getinnerframes\n",
      "    frameinfo = (tb.tb_frame,) + getframeinfo(tb, context)\n",
      "  File \"/home/aiffel0042/anaconda3/envs/aiffel/lib/python3.7/inspect.py\", line 1460, in getframeinfo\n",
      "    filename = getsourcefile(frame) or getfile(frame)\n",
      "  File \"/home/aiffel0042/anaconda3/envs/aiffel/lib/python3.7/inspect.py\", line 696, in getsourcefile\n",
      "    if getattr(getmodule(object, filename), '__loader__', None) is not None:\n",
      "  File \"/home/aiffel0042/anaconda3/envs/aiffel/lib/python3.7/inspect.py\", line 733, in getmodule\n",
      "    if ismodule(module) and hasattr(module, '__file__'):\n",
      "  File \"/home/aiffel0042/anaconda3/envs/aiffel/lib/python3.7/site-packages/tensorflow/__init__.py\", line 50, in __getattr__\n",
      "    module = self._load()\n",
      "  File \"/home/aiffel0042/anaconda3/envs/aiffel/lib/python3.7/site-packages/tensorflow/__init__.py\", line 44, in _load\n",
      "    module = _importlib.import_module(self.__name__)\n",
      "  File \"/home/aiffel0042/anaconda3/envs/aiffel/lib/python3.7/importlib/__init__.py\", line 127, in import_module\n",
      "    return _bootstrap._gcd_import(name[level:], package, level)\n",
      "  File \"<frozen importlib._bootstrap>\", line 1006, in _gcd_import\n",
      "  File \"<frozen importlib._bootstrap>\", line 983, in _find_and_load\n",
      "  File \"<frozen importlib._bootstrap>\", line 965, in _find_and_load_unlocked\n",
      "ModuleNotFoundError: No module named 'tensorflow_core.estimator'\n",
      "Traceback (most recent call last):\n",
      "  File \"/home/aiffel0042/anaconda3/envs/aiffel/lib/python3.7/site-packages/IPython/core/interactiveshell.py\", line 3418, in run_code\n",
      "    exec(code_obj, self.user_global_ns, self.user_ns)\n",
      "  File \"<ipython-input-3-2d4de0c6809b>\", line 1, in <module>\n",
      "    tf.__verion__\n",
      "AttributeError: module 'tensorflow' has no attribute '__verion__'\n",
      "\n",
      "During handling of the above exception, another exception occurred:\n",
      "\n",
      "Traceback (most recent call last):\n",
      "  File \"/home/aiffel0042/anaconda3/envs/aiffel/lib/python3.7/site-packages/IPython/core/interactiveshell.py\", line 2045, in showtraceback\n",
      "    stb = value._render_traceback_()\n",
      "AttributeError: 'AttributeError' object has no attribute '_render_traceback_'\n",
      "\n",
      "During handling of the above exception, another exception occurred:\n",
      "\n",
      "Traceback (most recent call last):\n",
      "  File \"/home/aiffel0042/anaconda3/envs/aiffel/lib/python3.7/site-packages/IPython/core/interactiveshell.py\", line 3338, in run_ast_nodes\n",
      "    if (await self.run_code(code, result,  async_=asy)):\n",
      "  File \"/home/aiffel0042/anaconda3/envs/aiffel/lib/python3.7/site-packages/IPython/core/interactiveshell.py\", line 3435, in run_code\n",
      "    self.showtraceback(running_compiled_code=True)\n",
      "  File \"/home/aiffel0042/anaconda3/envs/aiffel/lib/python3.7/site-packages/IPython/core/interactiveshell.py\", line 2048, in showtraceback\n",
      "    value, tb, tb_offset=tb_offset)\n",
      "  File \"/home/aiffel0042/anaconda3/envs/aiffel/lib/python3.7/site-packages/IPython/core/ultratb.py\", line 1437, in structured_traceback\n",
      "    self, etype, value, tb, tb_offset, number_of_lines_of_context)\n",
      "  File \"/home/aiffel0042/anaconda3/envs/aiffel/lib/python3.7/site-packages/IPython/core/ultratb.py\", line 1337, in structured_traceback\n",
      "    self, etype, value, tb, tb_offset, number_of_lines_of_context\n",
      "  File \"/home/aiffel0042/anaconda3/envs/aiffel/lib/python3.7/site-packages/IPython/core/ultratb.py\", line 1194, in structured_traceback\n",
      "    tb_offset)\n",
      "  File \"/home/aiffel0042/anaconda3/envs/aiffel/lib/python3.7/site-packages/IPython/core/ultratb.py\", line 1151, in format_exception_as_a_whole\n",
      "    last_unique, recursion_repeat = find_recursion(orig_etype, evalue, records)\n",
      "  File \"/home/aiffel0042/anaconda3/envs/aiffel/lib/python3.7/site-packages/IPython/core/ultratb.py\", line 451, in find_recursion\n",
      "    return len(records), 0\n",
      "TypeError: object of type 'NoneType' has no len()\n",
      "\n",
      "During handling of the above exception, another exception occurred:\n",
      "\n",
      "Traceback (most recent call last):\n",
      "  File \"/home/aiffel0042/anaconda3/envs/aiffel/lib/python3.7/site-packages/IPython/core/interactiveshell.py\", line 2045, in showtraceback\n",
      "    stb = value._render_traceback_()\n",
      "AttributeError: 'TypeError' object has no attribute '_render_traceback_'\n",
      "\n",
      "During handling of the above exception, another exception occurred:\n",
      "\n",
      "Traceback (most recent call last):\n",
      "  File \"/home/aiffel0042/anaconda3/envs/aiffel/lib/python3.7/site-packages/IPython/core/ultratb.py\", line 1170, in get_records\n",
      "    return _fixed_getinnerframes(etb, number_of_lines_of_context, tb_offset)\n",
      "  File \"/home/aiffel0042/anaconda3/envs/aiffel/lib/python3.7/site-packages/IPython/core/ultratb.py\", line 316, in wrapped\n",
      "    return f(*args, **kwargs)\n",
      "  File \"/home/aiffel0042/anaconda3/envs/aiffel/lib/python3.7/site-packages/IPython/core/ultratb.py\", line 350, in _fixed_getinnerframes\n",
      "    records = fix_frame_records_filenames(inspect.getinnerframes(etb, context))\n",
      "  File \"/home/aiffel0042/anaconda3/envs/aiffel/lib/python3.7/inspect.py\", line 1502, in getinnerframes\n",
      "    frameinfo = (tb.tb_frame,) + getframeinfo(tb, context)\n",
      "  File \"/home/aiffel0042/anaconda3/envs/aiffel/lib/python3.7/inspect.py\", line 1460, in getframeinfo\n",
      "    filename = getsourcefile(frame) or getfile(frame)\n",
      "  File \"/home/aiffel0042/anaconda3/envs/aiffel/lib/python3.7/inspect.py\", line 696, in getsourcefile\n",
      "    if getattr(getmodule(object, filename), '__loader__', None) is not None:\n",
      "  File \"/home/aiffel0042/anaconda3/envs/aiffel/lib/python3.7/inspect.py\", line 733, in getmodule\n",
      "    if ismodule(module) and hasattr(module, '__file__'):\n",
      "  File \"/home/aiffel0042/anaconda3/envs/aiffel/lib/python3.7/site-packages/tensorflow/__init__.py\", line 50, in __getattr__\n",
      "    module = self._load()\n",
      "  File \"/home/aiffel0042/anaconda3/envs/aiffel/lib/python3.7/site-packages/tensorflow/__init__.py\", line 44, in _load\n",
      "    module = _importlib.import_module(self.__name__)\n",
      "  File \"/home/aiffel0042/anaconda3/envs/aiffel/lib/python3.7/importlib/__init__.py\", line 127, in import_module\n",
      "    return _bootstrap._gcd_import(name[level:], package, level)\n",
      "  File \"<frozen importlib._bootstrap>\", line 1006, in _gcd_import\n",
      "  File \"<frozen importlib._bootstrap>\", line 983, in _find_and_load\n",
      "  File \"<frozen importlib._bootstrap>\", line 965, in _find_and_load_unlocked\n",
      "ModuleNotFoundError: No module named 'tensorflow_core.estimator'\n",
      "Traceback (most recent call last):\n",
      "  File \"/home/aiffel0042/anaconda3/envs/aiffel/lib/python3.7/site-packages/IPython/core/interactiveshell.py\", line 3418, in run_code\n",
      "    exec(code_obj, self.user_global_ns, self.user_ns)\n",
      "  File \"<ipython-input-3-2d4de0c6809b>\", line 1, in <module>\n",
      "    tf.__verion__\n",
      "AttributeError: module 'tensorflow' has no attribute '__verion__'\n",
      "\n",
      "During handling of the above exception, another exception occurred:\n",
      "\n",
      "Traceback (most recent call last):\n",
      "  File \"/home/aiffel0042/anaconda3/envs/aiffel/lib/python3.7/site-packages/IPython/core/interactiveshell.py\", line 2045, in showtraceback\n",
      "    stb = value._render_traceback_()\n",
      "AttributeError: 'AttributeError' object has no attribute '_render_traceback_'\n",
      "\n",
      "During handling of the above exception, another exception occurred:\n",
      "\n",
      "Traceback (most recent call last):\n",
      "  File \"/home/aiffel0042/anaconda3/envs/aiffel/lib/python3.7/site-packages/IPython/core/interactiveshell.py\", line 3338, in run_ast_nodes\n",
      "    if (await self.run_code(code, result,  async_=asy)):\n",
      "  File \"/home/aiffel0042/anaconda3/envs/aiffel/lib/python3.7/site-packages/IPython/core/interactiveshell.py\", line 3435, in run_code\n",
      "    self.showtraceback(running_compiled_code=True)\n",
      "  File \"/home/aiffel0042/anaconda3/envs/aiffel/lib/python3.7/site-packages/IPython/core/interactiveshell.py\", line 2048, in showtraceback\n",
      "    value, tb, tb_offset=tb_offset)\n",
      "  File \"/home/aiffel0042/anaconda3/envs/aiffel/lib/python3.7/site-packages/IPython/core/ultratb.py\", line 1437, in structured_traceback\n",
      "    self, etype, value, tb, tb_offset, number_of_lines_of_context)\n",
      "  File \"/home/aiffel0042/anaconda3/envs/aiffel/lib/python3.7/site-packages/IPython/core/ultratb.py\", line 1337, in structured_traceback\n",
      "    self, etype, value, tb, tb_offset, number_of_lines_of_context\n",
      "  File \"/home/aiffel0042/anaconda3/envs/aiffel/lib/python3.7/site-packages/IPython/core/ultratb.py\", line 1194, in structured_traceback\n",
      "    tb_offset)\n",
      "  File \"/home/aiffel0042/anaconda3/envs/aiffel/lib/python3.7/site-packages/IPython/core/ultratb.py\", line 1151, in format_exception_as_a_whole\n",
      "    last_unique, recursion_repeat = find_recursion(orig_etype, evalue, records)\n",
      "  File \"/home/aiffel0042/anaconda3/envs/aiffel/lib/python3.7/site-packages/IPython/core/ultratb.py\", line 451, in find_recursion\n",
      "    return len(records), 0\n",
      "TypeError: object of type 'NoneType' has no len()\n",
      "\n",
      "During handling of the above exception, another exception occurred:\n",
      "\n",
      "Traceback (most recent call last):\n",
      "  File \"/home/aiffel0042/anaconda3/envs/aiffel/lib/python3.7/site-packages/IPython/core/interactiveshell.py\", line 2045, in showtraceback\n",
      "    stb = value._render_traceback_()\n",
      "AttributeError: 'TypeError' object has no attribute '_render_traceback_'\n",
      "\n",
      "During handling of the above exception, another exception occurred:\n",
      "\n",
      "Traceback (most recent call last):\n",
      "  File \"/home/aiffel0042/anaconda3/envs/aiffel/lib/python3.7/site-packages/IPython/core/interactiveshell.py\", line 2923, in _run_cell\n",
      "    return runner(coro)\n",
      "  File \"/home/aiffel0042/anaconda3/envs/aiffel/lib/python3.7/site-packages/IPython/core/async_helpers.py\", line 68, in _pseudo_sync_runner\n",
      "    coro.send(None)\n",
      "  File \"/home/aiffel0042/anaconda3/envs/aiffel/lib/python3.7/site-packages/IPython/core/interactiveshell.py\", line 3147, in run_cell_async\n",
      "    interactivity=interactivity, compiler=compiler, result=result)\n",
      "  File \"/home/aiffel0042/anaconda3/envs/aiffel/lib/python3.7/site-packages/IPython/core/interactiveshell.py\", line 3357, in run_ast_nodes\n",
      "    self.showtraceback()\n",
      "  File \"/home/aiffel0042/anaconda3/envs/aiffel/lib/python3.7/site-packages/IPython/core/interactiveshell.py\", line 2048, in showtraceback\n",
      "    value, tb, tb_offset=tb_offset)\n",
      "  File \"/home/aiffel0042/anaconda3/envs/aiffel/lib/python3.7/site-packages/IPython/core/ultratb.py\", line 1437, in structured_traceback\n",
      "    self, etype, value, tb, tb_offset, number_of_lines_of_context)\n",
      "  File \"/home/aiffel0042/anaconda3/envs/aiffel/lib/python3.7/site-packages/IPython/core/ultratb.py\", line 1337, in structured_traceback\n",
      "    self, etype, value, tb, tb_offset, number_of_lines_of_context\n",
      "  File \"/home/aiffel0042/anaconda3/envs/aiffel/lib/python3.7/site-packages/IPython/core/ultratb.py\", line 1212, in structured_traceback\n",
      "    chained_exceptions_tb_offset)\n",
      "  File \"/home/aiffel0042/anaconda3/envs/aiffel/lib/python3.7/site-packages/IPython/core/ultratb.py\", line 1151, in format_exception_as_a_whole\n",
      "    last_unique, recursion_repeat = find_recursion(orig_etype, evalue, records)\n",
      "  File \"/home/aiffel0042/anaconda3/envs/aiffel/lib/python3.7/site-packages/IPython/core/ultratb.py\", line 451, in find_recursion\n",
      "    return len(records), 0\n",
      "TypeError: object of type 'NoneType' has no len()\n",
      "\n",
      "During handling of the above exception, another exception occurred:\n",
      "\n",
      "Traceback (most recent call last):\n",
      "  File \"/home/aiffel0042/anaconda3/envs/aiffel/lib/python3.7/site-packages/IPython/core/interactiveshell.py\", line 2045, in showtraceback\n",
      "    stb = value._render_traceback_()\n",
      "AttributeError: 'TypeError' object has no attribute '_render_traceback_'\n",
      "\n",
      "During handling of the above exception, another exception occurred:\n",
      "\n",
      "Traceback (most recent call last):\n",
      "  File \"/home/aiffel0042/anaconda3/envs/aiffel/lib/python3.7/site-packages/IPython/core/ultratb.py\", line 1170, in get_records\n",
      "    return _fixed_getinnerframes(etb, number_of_lines_of_context, tb_offset)\n",
      "  File \"/home/aiffel0042/anaconda3/envs/aiffel/lib/python3.7/site-packages/IPython/core/ultratb.py\", line 316, in wrapped\n",
      "    return f(*args, **kwargs)\n",
      "  File \"/home/aiffel0042/anaconda3/envs/aiffel/lib/python3.7/site-packages/IPython/core/ultratb.py\", line 350, in _fixed_getinnerframes\n",
      "    records = fix_frame_records_filenames(inspect.getinnerframes(etb, context))\n",
      "  File \"/home/aiffel0042/anaconda3/envs/aiffel/lib/python3.7/inspect.py\", line 1502, in getinnerframes\n",
      "    frameinfo = (tb.tb_frame,) + getframeinfo(tb, context)\n",
      "  File \"/home/aiffel0042/anaconda3/envs/aiffel/lib/python3.7/inspect.py\", line 1460, in getframeinfo\n",
      "    filename = getsourcefile(frame) or getfile(frame)\n",
      "  File \"/home/aiffel0042/anaconda3/envs/aiffel/lib/python3.7/inspect.py\", line 696, in getsourcefile\n",
      "    if getattr(getmodule(object, filename), '__loader__', None) is not None:\n",
      "  File \"/home/aiffel0042/anaconda3/envs/aiffel/lib/python3.7/inspect.py\", line 733, in getmodule\n",
      "    if ismodule(module) and hasattr(module, '__file__'):\n",
      "  File \"/home/aiffel0042/anaconda3/envs/aiffel/lib/python3.7/site-packages/tensorflow/__init__.py\", line 50, in __getattr__\n",
      "    module = self._load()\n",
      "  File \"/home/aiffel0042/anaconda3/envs/aiffel/lib/python3.7/site-packages/tensorflow/__init__.py\", line 44, in _load\n",
      "    module = _importlib.import_module(self.__name__)\n",
      "  File \"/home/aiffel0042/anaconda3/envs/aiffel/lib/python3.7/importlib/__init__.py\", line 127, in import_module\n",
      "    return _bootstrap._gcd_import(name[level:], package, level)\n",
      "  File \"<frozen importlib._bootstrap>\", line 1006, in _gcd_import\n",
      "  File \"<frozen importlib._bootstrap>\", line 983, in _find_and_load\n",
      "  File \"<frozen importlib._bootstrap>\", line 965, in _find_and_load_unlocked\n",
      "ModuleNotFoundError: No module named 'tensorflow_core.estimator'\n"
     ]
    }
   ],
   "source": [
    "tf.__verion__"
   ]
  },
  {
   "cell_type": "code",
   "execution_count": null,
   "metadata": {},
   "outputs": [],
   "source": [
    "import numpy as np\n",
    "import os\n",
    "\n",
    "data_path = os.getenv(\"HOME\")+'/aiffel/speech_recognition/data/speech_wav_8000.npz'\n",
    "speech_data = np.load(data_path)"
   ]
  },
  {
   "cell_type": "code",
   "execution_count": null,
   "metadata": {},
   "outputs": [],
   "source": [
    "print(\"Wave data shape : \", speech_data[\"wav_vals\"].shape)\n",
    "print(\"Label data shape : \", speech_data[\"label_vals\"].shape)"
   ]
  },
  {
   "cell_type": "code",
   "execution_count": null,
   "metadata": {},
   "outputs": [],
   "source": [
    "import librosa\n",
    "\n",
    "def wav2spec(wav, fft_size=258): # spectrogram shape을 맞추기위해서 size 변형\n",
    "    D = np.abs(librosa.stft(wav, n_fft=fft_size))\n",
    "    return D"
   ]
  }
 ],
 "metadata": {
  "kernelspec": {
   "display_name": "aiffel",
   "language": "python",
   "name": "aiffel"
  },
  "language_info": {
   "codemirror_mode": {
    "name": "ipython",
    "version": 3
   },
   "file_extension": ".py",
   "mimetype": "text/x-python",
   "name": "python",
   "nbconvert_exporter": "python",
   "pygments_lexer": "ipython3",
   "version": "3.7.6"
  }
 },
 "nbformat": 4,
 "nbformat_minor": 4
}
